<?xml version="1.0"?>

<robot name="my_robot" xmlns:xacro="http://www.ros.org/wiki/xacro">
    <xacro:include filename="$(find my_robot_urdf)/urdf/camera.urdf.xacro"/>

    <xacro:property name="pi" value="3.1415" />
    <xacro:property name="radius_wheel" value="0.04"/>
    <xacro:property name="radius_caster" value="0.025"/>
    <xacro:property name="length" value="0.02"/>
    <xacro:property name="wheel_mass" value="2.5" /> <!-- in kg-->
<!--     <xacro:property name="base_x_origin_to_caster_front_origin" value="0.115"/>
    <xacro:property name="base_z_origin_to_caster_front" value="0.007"/>
    <xacro:property name="base_x_origin_to_caster_back_origin" value="-0.135"/>
    <xacro:property name="base_z_origin_to_caster_back" value="0.009"/> -->
    
    <xacro:property name="base_y_origin_to_wheel_origin" value="0.15"/>
    

    <xacro:macro name="cylinder_inertia" params="m r h">
        <inertial>
            <mass value="${m}"/>
            <origin xyz="0 0 0" />
            <inertia ixx="${m*(3*r*r+h*h)/12}" ixy = "0" ixz = "0"
              iyy="${m*(3*r*r+h*h)/12}" iyz = "0"
              izz="${m*r*r/2}" />
        </inertial>
    </xacro:macro>

    <xacro:macro name="caster_inertia" params="m r">
        <inertial>
            <mass value="${m}"/>
            <origin xyz="0 0 0"/>
            <inertia ixx="${(2*m*r*r)/5}" ixy="0" ixz="0"
                iyy="${(2*m*r*r)/5}" iyz="0"
                izz="${(2*m*r*r)/5}" />
              
        </inertial>
    </xacro:macro>

    <xacro:macro name="cylinder_wheel" params="lr parent translateX translateY flipY"> <!--fb : front, back ; lr: left, right -->
         <link name="${lr}_wheel">
            <visual>
                <origin xyz="0 0 0" rpy="${flipY*pi/2} 0  0 " /> 
                <geometry>
                <cylinder length="${length}" radius="${radius_wheel}" />
                </geometry>
            </visual>
            <collision>
                <origin xyz="0 0 0" rpy="${flipY*pi/2} 0 0 " />
                <geometry>
                <cylinder length="${length}" radius="${radius_wheel}" />
                </geometry>
            </collision>
            <xacro:cylinder_inertia m="${wheel_mass}" r="${radius_wheel}" h="${length}" />
        </link>

        <gazebo reference="${lr}_wheel">
            <mu1 value="1.0"/>
            <mu2 value="1.0"/>
            <kp value="10000000.0"/>
            <kd value="1.0"/>
            <fdir1 value="1.0"/>
            <turnGravityOff>false</turnGravityOff>
        </gazebo>

        <joint name="${lr}_wheel_joint" type="continuous">
            <parent link="${parent}"/>
            <child link="${lr}_wheel"/>
            <origin xyz="0 ${translateY*base_y_origin_to_wheel_origin} 0" rpy="0 0 0"/>
            <axis xyz="0 1 0" rpy="0 0 0"/>
            <limit effort="100" velocity="100"/>
            <joint_properties damping="0.0" friction="0.0"/>
            
        </joint>
        <transmission name="${lr}_wheel_joint_trans">
            <type>transmission_interface/simpleTransmission</type>
            <joint name="${lr}_wheel_joint">
                <hardwareInterface>hardware_interface/VelocityJointInterface</hardwareInterface>
            </joint>
            <actuator name="${lr}_wheel_joint_motor">
                <mechanicalReduction>1</mechanicalReduction>
            </actuator>
        </transmission>
      
    </xacro:macro>

    <xacro:macro name="caster_wheel" params= "fb parent translateX base_x_origin_to_caster_origin base_z_origin_to_caster_origin">   <!--translateX=0 per front translateX=1 per back-->
        <link name="caster_${fb}_wheel">
            <visual>
                <origin xyz="${translateX*0.02}  0.02 0" rpy="1.57 0 0"/>
                <geometry>
                    <sphere radius="${radius_caster}"/>   
                </geometry>
            </visual>
            <collision>
                <origin xyz="${translateX*0.02}  0.02 0" rpy="1.57 0 0"/>
                <geometry>
                    <sphere radius="${radius_caster}"/>
                </geometry>
            </collision>
            <xacro:caster_inertia m="${wheel_mass}" r="${radius_caster}"/>
        </link>

        <joint name="caster_${fb}_joint" type="fixed">
            <parent link="${parent}"/>
            <child link="caster_${fb}_wheel"/>
            <origin xyz="${base_x_origin_to_caster_origin} 0 ${base_z_origin_to_caster_origin}" rpy="-1.57 0 0"/>
        </joint>

        <gazebo reference="caster_${fb}_wheel">
            <mu1 value="1.0"/>
            <mu2 value="1.0"/>
            <kp  value="10000000.0" />
            <kd  value="1.0" />
            <fdir1 value="1 0 0"/>
            <turnGravityOff>false</turnGravityOff>
        </gazebo>
    </xacro:macro>

    <link name="base_link">
        <visual>
        <geometry>
            <cylinder length="0.02" radius="0.15"/>
        </geometry>
        <origin rpy= "0 0 0" xyz= "0 0 0" />
        </visual>
        <xacro:cylinder_inertia m="5" r="0.15" h="0.02" />
    </link>

    <gazebo reference="base_link">
        <mu1 value="1.0"/>
        <mu2 value="1.0"/>
        <kp  value="10000000.0" />
        <kd  value="1.0" />
        <fdir1 value="1 0 0"/>
        <turnGravityOff>false</turnGravityOff>
    </gazebo>

    <xacro:cylinder_wheel  lr="left" parent="base_link" translateX="0" translateY="0.5" flipY="1" />
    <xacro:cylinder_wheel  lr="right" parent="base_link" translateX="0" translateY="-0.5" flipY="1" />

    <xacro:caster_wheel fb="front" parent="base_link" translateX="0" base_x_origin_to_caster_origin="0.115" base_z_origin_to_caster_origin="0.007" />
    <xacro:caster_wheel fb="back" parent="base_link" translateX="1" base_x_origin_to_caster_origin="-0.135" base_z_origin_to_caster_origin="0.009" />
    <xacro:mycameraRGB/>



    <gazebo>
        <plugin name="gazebo_ros_control" filename="libgazebo_ros_control.so">
            <robotNamespace>/</robotNamespace>
        </plugin>
    </gazebo>

     <gazebo>
        <plugin name="p3d_base_controller" filename="libgazebo_ros_p3d.so">
        <alwaysOn>true</alwaysOn>
        <updateRate>50.0</updateRate>
        <bodyName>base_link</bodyName>
        <topicName>ground_truth/state</topicName>
        <gaussianNoise>0.01</gaussianNoise>
        <frameName>map</frameName>
        <xyzOffsets>0 0 0</xyzOffsets>
        <rpyOffsets>0 0 0</rpyOffsets>
        </plugin>
    </gazebo>




</robot>